<?xml version="1.0" encoding="utf-8"?>
<!-- =================================================================================== -->
<!-- |    This document was autogenerated by xacro from gantry_robot.urdf.xacro        | -->
<!-- |    EDITING THIS FILE BY HAND IS NOT RECOMMENDED                                 | -->
<!-- =================================================================================== -->
<robot name="gantry_robot">
  <gazebo>
    <plugin filename="libgazebo_ros_control.so" name="ros_control">
      <!--robotNamespace>/slave</robotNamespace-->
      <!--robotSimType>gazebo_ros_control/DefaultRobotHWSim</robotSimType-->
      <legacyModeNS>true</legacyModeNS>
    </plugin>
  </gazebo>
  <transmission name="gantryX_trans">
    <type>transmission_interface/SimpleTransmission</type>
    <joint name="gantryX">
      <hardwareInterface>hardware_interface/PositionJointInterface</hardwareInterface>
    </joint>
    <actuator name="gantryX_motor">
      <mechanicalReduction>1</mechanicalReduction>
    </actuator>
  </transmission>
  <transmission name="gantryY_trans">
    <type>transmission_interface/SimpleTransmission</type>
    <joint name="gantryY">
      <hardwareInterface>hardware_interface/PositionJointInterface</hardwareInterface>
    </joint>
    <actuator name="gantryY_motor">
      <mechanicalReduction>1</mechanicalReduction>
    </actuator>
  </transmission>
  <transmission name="gantryZ_trans">
    <type>transmission_interface/SimpleTransmission</type>
    <joint name="gantryZ">
      <hardwareInterface>hardware_interface/PositionJointInterface</hardwareInterface>
    </joint>
    <actuator name="gantryZ_motor">
      <mechanicalReduction>1</mechanicalReduction>
    </actuator>
  </transmission>
  <transmission name="gantryYAW_trans">
    <type>transmission_interface/SimpleTransmission</type>
    <joint name="gantryYAW">
      <hardwareInterface>hardware_interface/PositionJointInterface</hardwareInterface>
    </joint>
    <actuator name="gantryYAW_motor">
      <mechanicalReduction>1</mechanicalReduction>
    </actuator>
  </transmission>
  <transmission name="gantryPITCH_trans">
    <type>transmission_interface/SimpleTransmission</type>
    <joint name="gantryPITCH">
      <hardwareInterface>hardware_interface/PositionJointInterface</hardwareInterface>
    </joint>
    <actuator name="gantryPITCH_motor">
      <mechanicalReduction>1</mechanicalReduction>
    </actuator>
  </transmission>
  <transmission name="gantryROLL_trans">
    <type>transmission_interface/SimpleTransmission</type>
    <joint name="gantryROLL">
      <hardwareInterface>hardware_interface/PositionJointInterface</hardwareInterface>
    </joint>
    <actuator name="gantryROLL_motor">
      <mechanicalReduction>1</mechanicalReduction>
    </actuator>
  </transmission>
  <gazebo reference="gantryX">
    <selfCollide>true</selfCollide>
  </gazebo>
  <gazebo reference="gantryY">
    <selfCollide>true</selfCollide>
  </gazebo>
  <gazebo reference="gantryZ">
    <selfCollide>true</selfCollide>
  </gazebo>
  <gazebo reference="gantryYAW">
    <selfCollide>true</selfCollide>
  </gazebo>
  <gazebo reference="gantryPITCH">
    <selfCollide>true</selfCollide>
  </gazebo>
  <gazebo reference="gantryROLL">
    <selfCollide>true</selfCollide>
  </gazebo>
  <link name="base_link">
    <!-- fixed structure -->
    <inertial>
      <mass value="1.0"/>
      <inertia ixx="1.0" ixy="0.0" ixz="0.0" iyy="1.0" iyz="0.0" izz="1.0"/>
    </inertial>
    <visual>
      <geometry>
        <mesh filename="package://gantry_description/meshes/Simulation_Base.STL"/>
      </geometry>
      <origin rpy="0 0 0" xyz="0.875 0 0"/>
      <material name="white">
        <color rgba="1 1 1 1"/>
      </material>
    </visual>
    <collision>
      <geometry>
        <mesh filename="package://gantry_description/meshes/Simulation_Base.STL"/>
      </geometry>
      <origin rpy="0 0 0" xyz="0.875 0 0"/>
    </collision>
  </link>
  <joint name="gantryX" type="prismatic">
    <parent link="base_link"/>
    <child link="gantryX_link"/>
    <limit effort="1" lower="0" upper="1.75" velocity="0.5"/>
    <axis xyz="1 0 0"/>
    <origin rpy="0 0 0" xyz="0 0 0.14288"/>
  </joint>
  <link name="gantryX_link">
    <inertial>
      <mass value="1.0"/>
      <inertia ixx="1.0" ixy="0.0" ixz="0.0" iyy="1.0" iyz="0.0" izz="1.0"/>
    </inertial>
    <visual>
      <geometry>
        <mesh filename="package://gantry_description/meshes/Simulation_X_Axis.STL"/>
      </geometry>
      <origin rpy="0 0 0" xyz="0 0 0.5461"/>
      <material name="blue">
        <color rgba="0 0 1 1"/>
      </material>
    </visual>
    <collision>
      <geometry>
        <mesh filename="package://gantry_description/meshes/Simulation_X_Axis.STL"/>
      </geometry>
      <origin rpy="0 0 0" xyz="0 0 0.5461"/>
    </collision>
  </link>
  <joint name="gantryY" type="prismatic">
    <parent link="gantryX_link"/>
    <child link="gantryY_link"/>
    <limit effort="1" lower="-0.5" upper="0.5" velocity="0.5"/>
    <axis xyz="0 1 0"/>
    <origin rpy="0 0 0" xyz="0.077 0 1.49793"/>
  </joint>
  <link name="gantryY_link">
    <inertial>
      <mass value="1.0"/>
      <inertia ixx="1.0" ixy="0.0" ixz="0.0" iyy="1.0" iyz="0.0" izz="1.0"/>
    </inertial>
    <visual>
      <geometry>
        <mesh filename="package://gantry_description/meshes/Simulation_Y_Axis.STL"/>
      </geometry>
      <origin rpy="0 0 0" xyz="0 0 0"/>
      <material name="green">
        <color rgba="0 1 0 1"/>
      </material>
    </visual>
    <collision>
      <geometry>
        <mesh filename="package://gantry_description/meshes/Simulation_Y_Axis.STL"/>
      </geometry>
      <origin rpy="0 0 0" xyz="0 0 0"/>
    </collision>
  </link>
  <joint name="gantryZ" type="prismatic">
    <parent link="gantryY_link"/>
    <child link="gantryZ_link"/>
    <limit effort="1" lower="0.0" upper="0.625" velocity="0.5"/>
    <axis xyz="0 0 -1"/>
    <origin rpy="0 0 0" xyz="0.09843 0 -0.5334"/>
    <!-- xyz="0.09843 0 -0.5334"  -->
  </joint>
  <link name="gantryZ_link">
    <inertial>
      <mass value="0.001"/>
      <inertia ixx="0.001" ixy="0.0" ixz="0.0" iyy="0.001" iyz="0.0" izz="0.001"/>
    </inertial>
    <visual>
      <geometry>
        <mesh filename="package://gantry_description/meshes/Simulation_Z_Axis.STL"/>
      </geometry>
      <origin rpy="0 1.5707 0" xyz="0 0 0"/>
      <material name="yellow">
        <color rgba="1 1 0 1"/>
      </material>
    </visual>
    <collision>
      <geometry>
        <mesh filename="package://gantry_description/meshes/Simulation_Z_Axis.STL"/>
      </geometry>
      <origin rpy="0 1.5707 0" xyz="0 0 0"/>
    </collision>
  </link>
  <!--  YAW ADDITION START -->
  <joint name="gantryYAW_Motor" type="fixed">
    <parent link="gantryZ_link"/>
    <child link="gantryYAW_Motor_link"/>
    <origin rpy="0 1.5707 0" xyz="0.0754 0.0 0.1"/>
    <!-- "0 1.5707 0" xyz="0.0754 0.0 0.1" -->
  </joint>
  <link name="gantryYAW_Motor_link">
    <inertial>
      <mass value="0.001"/>
      <inertia ixx="0.001" ixy="0.00" ixz="0.00" iyy="0.001" iyz="0.00" izz="0.001"/>
    </inertial>
    <visual>
      <geometry>
        <mesh filename="package://gantry_description/meshes/roll_motor.STL" scale="0.001 0.001 0.001"/>
      </geometry>
      <material name="white">
        <color rgba="1 0 0 1"/>
      </material>
    </visual>
    <origin rpy="0 0 0" xyz="0 0 0"/>
    <collision>
      <geometry>
        <mesh filename="package://gantry_description/meshes/roll_motor.STL" scale="0.001 0.001 0.001"/>
      </geometry>
    </collision>
  </link>
  <joint name="gantryYAW" type="revolute">
    <parent link="gantryZ_link"/>
    <child link="gantryYAW_link"/>
    <origin rpy="0 1.5707 0" xyz="0.075 0.0 0.1"/>
    <!-- xyz="0.0754 0.0 0.1" -->
    <limit effort="1" lower="-3.1415" upper="3.1415" velocity="3.15"/>
    <axis xyz="1 0 0"/>
  </joint>
  <link name="gantryYAW_link">
    <inertial>
      <mass value="0.001"/>
      <inertia ixx="0.001" ixy="0.00" ixz="0.00" iyy="0.001" iyz="0.00" izz="0.001"/>
    </inertial>
    <visual>
      <geometry>
        <mesh filename="package://gantry_description/meshes/roll_mini.STL" scale="0.001 0.001 0.001"/>
      </geometry>
      <material name="gold">
        <color rgba="1 0.84 0 1"/>
      </material>
    </visual>
    <origin rpy="0 0 0" xyz="0 0 0"/>
    <collision>
      <geometry>
        <mesh filename="package://gantry_description/meshes/roll_mini.STL" scale="0.001 0.001 0.001"/>
      </geometry>
    </collision>
  </link>
  <!--   YAW ADDITION END -->
  <!--  PITCH ADDITION START -->
  <joint name="gantryPITCH" type="revolute">
    <parent link="gantryYAW_link"/>
    <child link="gantryPITCH_link"/>
    <origin rpy="0 0 0" xyz="0.0859 0.0 0.0 "/>
    <limit effort="1" lower="-1.5707" upper="1.5707" velocity="3.15"/>
    <axis xyz="0 1 0"/>
  </joint>
  <link name="gantryPITCH_link">
    <inertial>
      <mass value="0.001"/>
      <inertia ixx="0.001" ixy="0.00" ixz="0.00" iyy="0.001" iyz="0.00" izz="0.001"/>
    </inertial>
    <visual>
      <geometry>
        <mesh filename="package://gantry_description/meshes/pitch.STL" scale="0.001 0.001 0.001"/>
      </geometry>
      <material name="green">
        <color rgba="0 1 0 1"/>
      </material>
    </visual>
    <origin rpy="1.5707 0 0" xyz="0 0 0"/>
    <collision>
      <geometry>
        <mesh filename="package://gantry_description/meshes/pitch.STL" scale="0.001 0.001 0.001"/>
      </geometry>
    </collision>
  </link>
  <!--  PITCH ADDITION END -->
  <!--  ROLL ADDITION START -->
  <joint name="gantryROLL" type="revolute">
    <parent link="gantryPITCH_link"/>
    <child link="gantryROLL_link"/>
    <origin rpy="0 0 0" xyz="0.098 0.0 0.0"/>
    <!-- xyz="0.098 0.0 0.0 -->
    <limit effort="1" lower="-3.1415" upper="3.1415" velocity="3.15"/>
    <axis xyz="1 0 0"/>
  </joint>
  <link name="gantryROLL_link">
    <inertial>
      <mass value="0.001"/>
      <inertia ixx="0.001" ixy="0.00" ixz="0.001" iyy="1.0" iyz="0.00" izz="0.001"/>
    </inertial>
    <visual>
      <geometry>
        <mesh filename="package://gantry_description/meshes/yaw.STL" scale="0.001 0.001 0.001"/>
      </geometry>
      <material name="deep_blue">
        <color rgba="0 0.75 1 1"/>
      </material>
    </visual>
    <origin rpy="1.5707 0 0" xyz="0 0 0"/>
    <collision>
      <geometry>
        <mesh filename="package://gantry_description/meshes/yaw.STL" scale="0.001 0.001 0.001"/>
      </geometry>
    </collision>
  </link>
  <!--  ROLL ADDITION END -->
  <!--  IN-HAND ADDITION START -->
  <joint name="inhand_cam_joint" type="fixed">
    <parent link="gantryROLL_link"/>
    <child link="inhand_link"/>
    <origin rpy="0.0 0.0 0.0" xyz="0.12403 0.0294 0.05638"/>
  </joint>
  <link name="inhand_link">
    <inertial>
      <mass value="0.001"/>
      <inertia ixx="0.001" ixy="0.00" ixz="0.001" iyy="1.0" iyz="0.00" izz="0.001"/>
    </inertial>
    <visual>
      <geometry>
        <mesh filename="package://gantry_description/meshes/in-hand.STL" scale="0.001 0.001 0.001"/>
      </geometry>
      <material name="grey">
        <color rgba="0.9 0.9 1 1"/>
      </material>
    </visual>
    <origin rpy="0 0 0" xyz="0 0 0"/>
    <collision>
      <geometry>
        <mesh filename="package://gantry_description/meshes/in-hand.STL" scale="0.001 0.001 0.001"/>
      </geometry>
    </collision>
  </link>
  <!--  IN-HAND ADDITION END -->
  <!--  GRIPPER ADDITION START-->
  <joint name="gripper_joint" type="fixed">
    <parent link="gantryROLL_link"/>
    <child link="gripper_link"/>
    <origin rpy="0.0 0.0 0.0" xyz="0.08738 0.017 0.0 "/>
    <!--"0.0875 0.0127 0"-->
  </joint>
  <link name="gripper_link">
    <inertial>
      <mass value="0.001"/>
      <inertia ixx="0.001" ixy="0.00" ixz="0.001" iyy="1.0" iyz="0.00" izz="0.001"/>
    </inertial>
    <visual>
      <geometry>
        <mesh filename="package://gantry_description/meshes/gripper.STL" scale="0.001 0.001 0.001"/>
      </geometry>
      <material name="grey">
        <color rgba="0.9 0.9 1 1"/>
      </material>
    </visual>
    <origin rpy="0 0 0" xyz="0 0 0"/>
    <collision>
      <geometry>
        <mesh filename="package://gantry_description/meshes/gripper.STL" scale="0.001 0.001 0.001"/>
      </geometry>
    </collision>
  </link>
  <!--  GRIPPER ADDITION END -->
  <joint name="ee_fixed_joint" type="fixed">
    <parent link="gripper_link"/>
    <child link="ee_link"/>
    <origin rpy="0.0 0.0 0.0" xyz="0.156 0.00925 -0.03188"/>
    <!-- xyz="0.225 0 -0.03175" 0.24 0 0 -->
  </joint>
  <link name="ee_link">
    <origin rpy="0 0 0" xyz="0 0 0"/>
    <collision>
      <geometry>
        <box size="0.015 0.015 0.015"/>
      </geometry>
    </collision>
    <inertial>
      <mass value="0.001"/>
      <inertia ixx="0.001" ixy="0.0" ixz="0.0" iyy="0.001" iyz="0.0" izz="0.001"/>
    </inertial>
  </link>
  <!-- ROS base_link to UR 'Base' Coordinates transform -->
  <!--link name="base"/>
  <joint name="base_link-base_fixed_joint" type="fixed">
      <origin xyz="0 0 0" rpy="0 0 0"/>
      <parent link="${prefix}base_link"/>
      <child link="${prefix}base"/>
    </joint-->
  <!-- Frame coincident with all-zeros TCP on UR controller -->
  <!--link name="${prefix}tool0"/>
    <joint name="${prefix}gantryYAW_link-tool0_fixed_joint" type="fixed">
      <origin xyz="0 0 -0.24" rpy="0 0 0"/>
      <parent link="${prefix}gantryYAW_link"/>
      <child link="${prefix}tool0"/>
    </joint-->
  <!--link name="world" />
    <joint name="world_joint" type="fixed">
        <parent link="world" />
        <child link="base_link" />
        <origin rpy="0.0 0.0 0.0" xyz="0.0 0.0 0.0" />
    </joint-->
  <!--transmission name="trans_gantryX">
        <type>transmission_interface/SimpleTransmission</type>
        <joint name="gantryX">
            <hardwareInterface>hardware_interface/PositionJointInterface</hardwareInterface>
        </joint>
        <actuator name="gantryX_motor">
            <hardwareInterface>hardware_interface/PositionJointInterface</hardwareInterface>
            <mechanicalReduction>1</mechanicalReduction>
        </actuator>
    </transmission>

    <transmission name="trans_gantryY">
        <type>transmission_interface/SimpleTransmission</type>
        <joint name="gantryY">
            <hardwareInterface>hardware_interface/PositionJointInterface</hardwareInterface>
        </joint>
        <actuator name="gantryY_motor">
            <hardwareInterface>hardware_interface/PositionJointInterface</hardwareInterface>
            <mechanicalReduction>1</mechanicalReduction>
        </actuator>
    </transmission>

    <transmission name="trans_gantryZ">
        <type>transmission_interface/SimpleTransmission</type>
        <joint name="gantryZ">
            <hardwareInterface>hardware_interface/PositionJointInterface</hardwareInterface>
        </joint>
        <actuator name="gantryZ_motor">
            <hardwareInterface>hardware_interface/PositionJointInterface</hardwareInterface>
            <mechanicalReduction>1</mechanicalReduction>
        </actuator>
    </transmission>

    <gazebo>
        <plugin name="gazebo_ros_control" filename="libgazebo_ros_control.so">
            <robotNamespace>/</robotNamespace>
        </plugin>
    </gazebo-->
  <!-- base plate link definition -->
  <link name="base_plate">
    <inertial>
      <mass value="1.0"/>
      <inertia ixx="1.0" ixy="0.0" ixz="0.0" iyy="1.0" iyz="0.0" izz="1.0"/>
    </inertial>
    <visual>
      <geometry>
        <mesh filename="package://gantry_description/meshes/gantry_base_plate.stl"/>
      </geometry>
      <origin rpy="0 0 0" xyz="-1.25 -0.6 -0.01"/>
      <material name="light_green">
        <color rgba="0.56 0.93 0.56 1"/>
      </material>
    </visual>
    <collision>
      <geometry>
        <mesh filename="package://gantry_description/meshes/gantry_base_plate.stl"/>
      </geometry>
      <origin rpy="0 0 0" xyz="-1.25 -0.6 -0.01"/>
    </collision>
  </link>
  <!-- Fixed joints to attach the base plate -->
  <joint name="base_plate_to_side" type="fixed">
    <parent link="base_link"/>
    <child link="base_plate"/>
    <origin rpy="0 0 0" xyz="0.91 0 0.255"/>
  </joint>
  <!-- Plant Pot 1 (Visual Only, No Collision, Light Green Color) -->
  <link name="plant_pot_1">
    <visual>
      <geometry>
        <mesh filename="package://gantry_description/meshes/plantpot.stl" scale="0.1 0.1 0.1"/>
      </geometry>
      <origin rpy="1.57 0 0" xyz="0.14 0.4 0"/>
      <material name="light_green">
        <color rgba="0.56 0.93 0.56 1"/>
      </material>
    </visual>
  </link>
  <joint name="plant_pot_1_joint" type="fixed">
    <parent link="base_plate"/>
    <child link="plant_pot_1"/>
    <origin rpy="0 0 0" xyz="0 0 0"/>
  </joint>
  <!-- Plant Pot 2 (Visual Only, No Collision, Light Green Color) -->
  <link name="plant_pot_2">
    <visual>
      <geometry>
        <mesh filename="package://gantry_description/meshes/plantpot.stl" scale="0.1 0.1 0.1"/>
      </geometry>
      <origin rpy="1.57 0 0" xyz="0.14 0.325 0"/>
      <material name="light_green">
        <color rgba="0.56 0.93 0.56 1"/>
      </material>
    </visual>
  </link>
  <joint name="plant_pot_2_joint" type="fixed">
    <parent link="base_plate"/>
    <child link="plant_pot_2"/>
    <origin rpy="0 0 0" xyz="0 0 0"/>
  </joint>
  <!--  <link name="world" />-->
  <!--  <joint name="world_joint" type="fixed">-->
  <!--    <parent link="world" />-->
  <!--    <child link = "base_link" />-->
  <!--    <origin xyz="0.0 0.0 0.0" rpy="0.0 0.0 0.0" />-->
  <!--  </joint>-->
</robot>

